import math

# print('Значение под корнем не может быть отрицательным,'
#       'поэтому этот код не выполнится', math.sqrt(-1), 'и вызовет исключение "ValueError"')

# Но, в связи с тем что оператор and проверяет второй операнд тогда и только тогда, когда первый вернул True
if 1 > 2 and math.sqrt(-1):
    print('Ошибки не будет, так как первое условие вернет False')
print('Двигаемся дальше')

# Первая Ложь
print([1] and [] and '' and 1)

# Последняя Истина
print([1] and 1 and 20 and 1.1)